Workbook

Sheet Control
A1: EVE · 03 CANONICAL CATALOG · CHIP RECTOR v0.1
A3: Metadato | B3: Valor | D3: KPI | E3: Valor
A4: chip_id | B4: EVE-03-CANONICAL-CATALOG | D4: Nodos canónicos | E4: =COUNTA(source_node_registry!C2:C165)
A5: package_id | B5: EVE_03_Canonical_Catalog_v0_1 | D5: Códigos fuente | E5: =COUNTA(source_code_registry!A2:A165)
A6: version | B6: 0.1.0 | D6: Variables registry | E6: =COUNTA(canonical_variables!A2:A258)
A7: estado calculado | B7: =IF(COUNTIF(canonical_variables!C2:C258,"referenced_not_defined_in_variables_source")>0,"READY_WITH_FLAGS","READY") | D7: Rutas críticas | E7: =COUNTA(critical_routes!A2:A5)
A8: generado UTC | B8: 46191.688 | D8: Políticas globales | E8: =COUNTIF(epistemic_policy!B2:B175,"global")
A9: fuente canónica | B9: D8 · EVE_Catalogo_Madre_Capa1_v1_0_Bloques_0_0_5_1_7.xlsx | D9: Políticas por nodo | E9: =COUNTIF(epistemic_policy!B2:B175,"node")
A10: dictamen | B10: READY_WITH_FLAGS: genealogía íntegra; variables pendientes explícitas; VSM solo preparatorio. | D10: Variables pendientes | E10: =COUNTIF(canonical_variables!C2:C258,"referenced_not_defined_in_variables_source")
A11: not_a_prompt | B11: TRUE | D11: Nombres duplicados fuente | E11: =COUNTIF(canonical_variables!F2:F258,">1")
A12: package_aliases | B12: EVE_03_Canonical_Catalog_Chip_v0_1 | D12: Miembros de rutas críticas | E12: =SUM(critical_routes!H2:H5)
A13: Inventario por bloque
A14: Bloque | B14: Nodos | C14: Base | D14: Condicional | E14: Aclaración | F14: Causal | G14: Interna | H14: Confirmación
A15: 0 | B15: =COUNTIF(source_node_registry!$E$2:$E$165,A15) | C15: =COUNTIFS(source_node_registry!$E$2:$E$165,A15,source_node_registry!$N$2:$N$165,"base_question") | D15: =COUNTIFS(source_node_registry!$E$2:$E$165,A15,source_node_registry!$N$2:$N$165,"conditional_question") | E15: =COUNTIFS(source_node_registry!$E$2:$E$165,A15,source_node_registry!$N$2:$N$165,"clarification_node") | F15: =COUNTIFS(source_node_registry!$E$2:$E$165,A15,source_node_registry!$N$2:$N$165,"causal_probe") | G15: =COUNTIFS(source_node_registry!$E$2:$E$165,A15,source_node_registry!$N$2:$N$165,"internal_derivation") | H15: =COUNTIFS(source_node_registry!$E$2:$E$165,A15,source_node_registry!$N$2:$N$165,"confirmation_card")
A16: 0.5 | B16: =COUNTIF(source_node_registry!$E$2:$E$165,A16) | C16: =COUNTIFS(source_node_registry!$E$2:$E$165,A16,source_node_registry!$N$2:$N$165,"base_question") | D16: =COUNTIFS(source_node_registry!$E$2:$E$165,A16,source_node_registry!$N$2:$N$165,"conditional_question") | E16: =COUNTIFS(source_node_registry!$E$2:$E$165,A16,source_node_registry!$N$2:$N$165,"clarification_node") | F16: =COUNTIFS(source_node_registry!$E$2:$E$165,A16,source_node_registry!$N$2:$N$165,"causal_probe") | G16: =COUNTIFS(source_node_registry!$E$2:$E$165,A16,source_node_registry!$N$2:$N$165,"internal_derivation") | H16: =COUNTIFS(source_node_registry!$E$2:$E$165,A16,source_node_registry!$N$2:$N$165,"confirmation_card")
A17: 1 | B17: =COUNTIF(source_node_registry!$E$2:$E$165,A17) | C17: =COUNTIFS(source_node_registry!$E$2:$E$165,A17,source_node_registry!$N$2:$N$165,"base_question") | D17: =COUNTIFS(source_node_registry!$E$2:$E$165,A17,source_node_registry!$N$2:$N$165,"conditional_question") | E17: =COUNTIFS(source_node_registry!$E$2:$E$165,A17,source_node_registry!$N$2:$N$165,"clarification_node") | F17: =COUNTIFS(source_node_registry!$E$2:$E$165,A17,source_node_registry!$N$2:$N$165,"causal_probe") | G17: =COUNTIFS(source_node_registry!$E$2:$E$165,A17,source_node_registry!$N$2:$N$165,"internal_derivation") | H17: =COUNTIFS(source_node_registry!$E$2:$E$165,A17,source_node_registry!$N$2:$N$165,"confirmation_card")
A18: 2 | B18: =COUNTIF(source_node_registry!$E$2:$E$165,A18) | C18: =COUNTIFS(source_node_registry!$E$2:$E$165,A18,source_node_registry!$N$2:$N$165,"base_question") | D18: =COUNTIFS(source_node_registry!$E$2:$E$165,A18,source_node_registry!$N$2:$N$165,"conditional_question") | E18: =COUNTIFS(source_node_registry!$E$2:$E$165,A18,source_node_registry!$N$2:$N$165,"clarification_node") | F18: =COUNTIFS(source_node_registry!$E$2:$E$165,A18,source_node_registry!$N$2:$N$165,"causal_probe") | G18: =COUNTIFS(source_node_registry!$E$2:$E$165,A18,source_node_registry!$N$2:$N$165,"internal_derivation") | H18: =COUNTIFS(source_node_registry!$E$2:$E$165,A18,source_node_registry!$N$2:$N$165,"confirmation_card")
A19: 3 | B19: =COUNTIF(source_node_registry!$E$2:$E$165,A19) | C19: =COUNTIFS(source_node_registry!$E$2:$E$165,A19,source_node_registry!$N$2:$N$165,"base_question") | D19: =COUNTIFS(source_node_registry!$E$2:$E$165,A19,source_node_registry!$N$2:$N$165,"conditional_question") | E19: =COUNTIFS(source_node_registry!$E$2:$E$165,A19,source_node_registry!$N$2:$N$165,"clarification_node") | F19: =COUNTIFS(source_node_registry!$E$2:$E$165,A19,source_node_registry!$N$2:$N$165,"causal_probe") | G19: =COUNTIFS(source_node_registry!$E$2:$E$165,A19,source_node_registry!$N$2:$N$165,"internal_derivation") | H19: =COUNTIFS(source_node_registry!$E$2:$E$165,A19,source_node_registry!$N$2:$N$165,"confirmation_card")
A20: 4 | B20: =COUNTIF(source_node_registry!$E$2:$E$165,A20) | C20: =COUNTIFS(source_node_registry!$E$2:$E$165,A20,source_node_registry!$N$2:$N$165,"base_question") | D20: =COUNTIFS(source_node_registry!$E$2:$E$165,A20,source_node_registry!$N$2:$N$165,"conditional_question") | E20: =COUNTIFS(source_node_registry!$E$2:$E$165,A20,source_node_registry!$N$2:$N$165,"clarification_node") | F20: =COUNTIFS(source_node_registry!$E$2:$E$165,A20,source_node_registry!$N$2:$N$165,"causal_probe") | G20: =COUNTIFS(source_node_registry!$E$2:$E$165,A20,source_node_registry!$N$2:$N$165,"internal_derivation") | H20: =COUNTIFS(source_node_registry!$E$2:$E$165,A20,source_node_registry!$N$2:$N$165,"confirmation_card")
A21: 5 | B21: =COUNTIF(source_node_registry!$E$2:$E$165,A21) | C21: =COUNTIFS(source_node_registry!$E$2:$E$165,A21,source_node_registry!$N$2:$N$165,"base_question") | D21: =COUNTIFS(source_node_registry!$E$2:$E$165,A21,source_node_registry!$N$2:$N$165,"conditional_question") | E21: =COUNTIFS(source_node_registry!$E$2:$E$165,A21,source_node_registry!$N$2:$N$165,"clarification_node") | F21: =COUNTIFS(source_node_registry!$E$2:$E$165,A21,source_node_registry!$N$2:$N$165,"causal_probe") | G21: =COUNTIFS(source_node_registry!$E$2:$E$165,A21,source_node_registry!$N$2:$N$165,"internal_derivation") | H21: =COUNTIFS(source_node_registry!$E$2:$E$165,A21,source_node_registry!$N$2:$N$165,"confirmation_card")
A22: 6 | B22: =COUNTIF(source_node_registry!$E$2:$E$165,A22) | C22: =COUNTIFS(source_node_registry!$E$2:$E$165,A22,source_node_registry!$N$2:$N$165,"base_question") | D22: =COUNTIFS(source_node_registry!$E$2:$E$165,A22,source_node_registry!$N$2:$N$165,"conditional_question") | E22: =COUNTIFS(source_node_registry!$E$2:$E$165,A22,source_node_registry!$N$2:$N$165,"clarification_node") | F22: =COUNTIFS(source_node_registry!$E$2:$E$165,A22,source_node_registry!$N$2:$N$165,"causal_probe") | G22: =COUNTIFS(source_node_registry!$E$2:$E$165,A22,source_node_registry!$N$2:$N$165,"internal_derivation") | H22: =COUNTIFS(source_node_registry!$E$2:$E$165,A22,source_node_registry!$N$2:$N$165,"confirmation_card")
A23: 7 | B23: =COUNTIF(source_node_registry!$E$2:$E$165,A23) | C23: =COUNTIFS(source_node_registry!$E$2:$E$165,A23,source_node_registry!$N$2:$N$165,"base_question") | D23: =COUNTIFS(source_node_registry!$E$2:$E$165,A23,source_node_registry!$N$2:$N$165,"conditional_question") | E23: =COUNTIFS(source_node_registry!$E$2:$E$165,A23,source_node_registry!$N$2:$N$165,"clarification_node") | F23: =COUNTIFS(source_node_registry!$E$2:$E$165,A23,source_node_registry!$N$2:$N$165,"causal_probe") | G23: =COUNTIFS(source_node_registry!$E$2:$E$165,A23,source_node_registry!$N$2:$N$165,"internal_derivation") | H23: =COUNTIFS(source_node_registry!$E$2:$E$165,A23,source_node_registry!$N$2:$N$165,"confirmation_card")
A26: Banderas de control
A27: ID | B27: Hallazgo | C27: Estado | D27: Acción
A28: FLAG-01 | B28: 33 variables referenciadas por nodos no aparecen definidas en Variables_Canonicas_Source. | C28: pending_variable_definition | D28: No inventar definición; resolver contra fuente o aprobar definición nueva.
A29: FLAG-02 | B29: 23 nombres de variable aparecen más de una vez en la fuente; 5 contienen variantes de definición. | C29: duplicate_definition_flag | D29: Preservar ocurrencias; resolver conflicto antes de certificar.
A30: BOUNDARY-VSM | B30: Los mappings VSM/AHE son preparación de Capa 1. | C30: candidate_signal_only | D30: No emitir diagnóstico VSM, recursión ni arquetipo desde este chip.
A31: BOUNDARY-EVE | B31: El catálogo conserva genealogía y evidencia; no emite diagnóstico final. | C31: no_final_diagnosis | D31: Conformance/consistencia/readiness preceden interpretación.
A34: Autoridad documental aplicada
A35: ID | B35: Documento | C35: Uso en Fase 3
A36: D8 | B36: Catálogo Madre XLSX | C36: Fuente canónica de genealogía, nodos, códigos, variables y rutas.
A37: D7 | B37: Arquitectura Runtime 40/20 | C37: Frontera: reducción visible ocurre en runtime, sin destruir genealogía.
A38: D5 | B38: Catálogo Runtime DOCX | C38: Gobierno normativo y fronteras.
A39: D6 | B39: Catálogo Runtime XLSX | C39: Compatibilidad ejecutable 40+20 y política epistemológica.
A40: VSM1 | B40: Organizational Systems | C40: Guardia metodológica VSM: identidad, variedad, recursión, discreción e información.

Sheet source_node_registry
A1: registry_version | B1: source_catalog_version | C1: source_node_ref_id | D1: master_node_id | E1: source_block | F1: block_sequence | G1: source_question_code_intact | H1: source_document | I1: source_document_version | J1: source_document_role | K1: source_document_status | L1: source_table_index | M1: node_status | N1: node_type | O1: runtime_role | P1: causal_function | Q1: original_catalog_question_text | R1: catalog_condition | S1: visible_question_text | T1: visibility_rule | U1: required_rule | V1: canonical_variable_output | W1: canonical_route_id | X1: route_status | Y1: is_critical_route_member | Z1: critical_route_ids | AA1: epistemic_status_raw | AB1: epistemic_status_normalized | AC1: provenance_type_raw | AD1: provenance_type_normalized | AE1: confirmation_policy | AF1: must_not_infer | AG1: audit_requirement | AH1: mmabp_quadrant_primary | AI1: mmabp_quadrant_secondary | AJ1: structural_fact_candidate | AK1: structural_fact_type | AL1: conformance_checkpoint | AM1: consistency_checkpoint | AN1: vsm_signal_allowed | AO1: vsm_system_candidates_raw | AP1: vsm_system_candidates_normalized | AQ1: ahe_signal_allowed | AR1: vsm_ahe_use_limit | AS1: diagnostic_criticality | AT1: downstream_object | AU1: governance_issue_type_if_missing | AV1: carry_forward_rule | AW1: risk_if_missing | AX1: source_row_fingerprint_sha256
A2: 0.1.0 | B2: 1.0 | C2: B0_0_0 | D2: C1B0-001 | E2: 0 | F2: 1 | G2: 0.0 | H2: Bloque_0_Documento_Madre_Capa1_v2_1_EVE_rev4_redisenado_robusto.docx | I2: Versión del documento: 0.4 de trabajo | Rediseño controlado B0-UX-SEM-001 | Entrada robusta desde WorkMapIntake con actividad completa, parcial, no estructurada o mínima | Mantiene compatibilidad interna con scene_anchor_bundle. | J2: Fuente canónica de nodos | K2: Fuente final aprobada | L2: 11 | M2: active | N2: internal_derivation | O2: interna_derivable | P2: anclaje_semantico | Q2: Cargar actividad declarada y estado de calidad semántica desde WorkMapIntake. | R2: Siempre que exista actividad proveniente de WorkMapIntake, aunque la estructura sea parcial o fallida | S2: Carga interna de activity_literal_from_workmap y estado de calidad semántica desde WorkMapIntake. | T2: No visible | U2: Obligatoria si existe actividad previa. Si la actividad llegó sin estructura usable, activar modo de reconstrucción guiada en 0.1/0.1a/0.2. | V2: semantic_preload_used + activity_semantic_* + semantic_review_attempt_count + block0_entry_mode | W2: CR-B0-WorkMapIntake-semantic-entry | X2: ruta_crítica | Y2: TRUE | Z2: CR-B0-WorkMapIntake-semantic-entry | AA2: source_reference / ai_inferred_unconfirmed / weak_context | AB2: source_reference | ai_inferred_unconfirmed | weak_context | AC2: source_reference / ai_inferred_unconfirmed / weak_context | AD2: source_reference | ai_inferred_unconfirmed | weak_context | AE2: Confirmar si baja confianza | AF2: No inferir como captured_user_evidence; exigir confirmación si afecta ruta canónica. | AG2: Audit log requerido si se deriva, corrige, bloquea o modifica ruta crítica. | AH2: Governance/Readiness | AI2: PM; PF | AJ2: No directo | AK2: scene_anchor | AL2: Actividad confirmada o reconstruida por usuario; no inferencia no confirmada. | AM2: B0↔B0.5; B0↔B1; B0↔B2 | AN2: Débil | AO2: S1; canal algedónico si no puede delimitarse | AP2: S1 | algedonic_channel | AQ2: No | AR2: flag de calidad narrativa; no diagnóstico | AS2: bloqueante/ruta_crítica | AT2: SceneCanonicalRecord; EvidenceBundle; MDSB | AU2: CanonicalRouteException | AV2: blocked_or_reentry_required | AW2: El usuario deberá capturar más manualmente; no invalida el bloque ni autoriza inferencias de IA no trazadas. | AX2: bfe5d644d059aad5936bb736dd874ab64941f757dc4e402346ae53b44ff5ffaa
A3: 0.1.0 | B3: 1.0 | C3: B0_0_1 | D3: C1B0-002 | E3: 0 | F3: 2 | G3: 0.1 | H3: Bloque_0_Documento_Madre_Capa1_v2_1_EVE_rev4_redisenado_robusto.docx | I3: Versión del documento: 0.4 de trabajo | Rediseño controlado B0-UX-SEM-001 | Entrada robusta desde WorkMapIntake con actividad completa, parcial, no estructurada o mínima | Mantiene compatibilidad interna con scene_anchor_bundle. | J3: Fuente canónica de nodos | K3: Fuente final aprobada | L3: 12 | M3: active | N3: confirmation_card | O3: confirmacion_asistida | P3: anclaje_semantico | Q3: Esto es lo que entendimos de esta actividad. ¿Está correcto? | R3: Siempre; si no hay preload, funciona como captura inicial guiada | S3: Esto es lo que entendimos de esta actividad. ¿Está correcto? | T3: Siempre | U3: Obligatoria | V3: activity_name_user_confirmed + semantic_confirmation_status + block0_entry_mode | W3: CR-B0-WorkMapIntake-semantic-entry | X3: ruta_crítica | Y3: TRUE | Z3: CR-B0-WorkMapIntake-semantic-entry | AA3: user_confirmed_evidence / user_corrected_evidence / reconstructed_user_evidence | AB3: user_confirmed_evidence | user_corrected_evidence | reconstructed_user_evidence | AC3: user_confirmed_evidence / user_corrected_evidence / reconstructed_user_evidence | AD3: user_confirmed_evidence | user_corrected_evidence | reconstructed_user_evidence | AE3: Confirmar siempre | AF3: No inferir como captured_user_evidence; exigir confirmación si afecta ruta canónica. | AG3: Audit log requerido si se deriva, corrige, bloquea o modifica ruta crítica. | AH3: Governance/Readiness | AI3: PM; PF | AJ3: No directo | AK3: scene_anchor | AL3: Actividad confirmada o reconstruida por usuario; no inferencia no confirmada. | AM3: B0↔B0.5; B0↔B1; B0↔B2 | AN3: Débil | AO3: S1; canal algedónico si no puede delimitarse | AP3: S1 | algedonic_channel | AQ3: No | AR3: flag de calidad narrativa; no diagnóstico | AS3: bloqueante/ruta_crítica | AT3: SceneCanonicalRecord; EvidenceBundle; MDSB | AU3: CanonicalRouteException | AV3: blocked_or_reentry_required | AW3: La plataforma trataría una sugerencia o una estructura fallida como evidencia sin autorización del usuario. | AX3: d5bf7b09ca79f5bffd444654d525892672f3f1d73e626b197ff6390dbf3ae737
A4: 0.1.0 | B4: 1.0 | C4: B0_0_1a | D4: C1B0-003 | E4: 0 | F4: 3 | G4: 0.1a | H4: Bloque_0_Documento_Madre_Capa1_v2_1_EVE_rev4_redisenado_robusto.docx | I4: Versión del documento: 0.4 de trabajo | Rediseño controlado B0-UX-SEM-001 | Entrada robusta desde WorkMapIntake con actividad completa, parcial, no estructurada o mínima | Mantiene compatibilidad interna con scene_anchor_bundle. | J4: Fuente canónica de nodos | K4: Fuente final aprobada | L4: 13 | M4: active | N4: conditional_question | O4: condicional | P4: anclaje_semantico | Q4: Corrige la frase para que diga claramente qué haces, sobre qué trabajas y qué queda listo. | R4: Si 0.1 = corregir / baja confianza | S4: Corrige la frase para que diga claramente qué haces, sobre qué trabajas y qué queda listo. | T4: Solo si el usuario corrige, si la confianza semántica es baja o si block0_entry_mode exige reconstrucción | U4: Obligatoria si 0.1 no se confirma, si la estructura llegó parcial o si la asistencia previa falló después de dos intentos | V4: activity_name_user_confirmed + activity_semantic_structure_corrected + reconstructed_activity_minimum | W4: CR-B0-WorkMapIntake-semantic-entry | X4: ruta_crítica | Y4: TRUE | Z4: CR-B0-WorkMapIntake-semantic-entry | AA4: user_corrected_evidence | AB4: user_corrected_evidence | AC4: user_corrected_evidence | AD4: user_corrected_evidence | AE4: No aplica / captura directa | AF4: No inferir como captured_user_evidence; exigir confirmación si afecta ruta canónica. | AG4: Audit log requerido si se deriva, corrige, bloquea o modifica ruta crítica. | AH4: Governance/Readiness | AI4: PM; PF | AJ4: No directo | AK4: scene_anchor | AL4: Actividad confirmada o reconstruida por usuario; no inferencia no confirmada. | AM4: B0↔B0.5; B0↔B1; B0↔B2 | AN4: Débil | AO4: S1; canal algedónico si no puede delimitarse | AP4: S1 | algedonic_channel | AQ4: No | AR4: flag de calidad narrativa; no diagnóstico | AS4: bloqueante/ruta_crítica | AT4: SceneCanonicalRecord; EvidenceBundle; MDSB | AU4: CanonicalRouteException | AV4: blocked_or_reentry_required | AW4: El bloque conservaría una actividad mal entendida y arrastraría el error a 0.5–7. | AX4: 4bf047bc22c042138c40b3ea83d42f4b7d35d8d3db96719a2ceaa851f3f2cfb6
A5: 0.1.0 | B5: 1.0 | C5: B0_0_2 | D5: C1B0-004 | E5: 0 | F5: 4 | G5: 0.2 | H5: Bloque_0_Documento_Madre_Capa1_v2_1_EVE_rev4_redisenado_robusto.docx | I5: Versión del documento: 0.4 de trabajo | Rediseño controlado B0-UX-SEM-001 | Entrada robusta desde WorkMapIntake con actividad completa, parcial, no estructurada o mínima | Mantiene compatibilidad interna con scene_anchor_bundle. | J5: Fuente canónica de nodos | K5: Fuente final aprobada | L5: 14 | M5: active | N5: base_question | O5: base | P5: anclaje_semantico | Q5: En tus palabras, ¿qué ocurre cuando haces esta actividad? | R5: Siempre; puede venir sugerida por IA | S5: En tus palabras, ¿qué ocurre cuando haces esta actividad? | T5: Siempre | U5: Obligatoria salvo que 0.1 incluya una descripción suficiente y el usuario la confirme explícitamente | V5: activity_summary_literal / scene_summary_literal | X5: normal | Y5: FALSE | AA5: captured_user_evidence or user_confirmed_suggestion | AB5: user_confirmed_suggestion | captured_user_evidence | AC5: captured_user_evidence or user_confirmed_suggestion | AD5: user_confirmed_suggestion | captured_user_evidence | AE5: No aplica / captura directa | AF5: No inferir como captured_user_evidence; exigir confirmación si afecta ruta canónica. | AG5: Audit log requerido si se deriva, corrige, bloquea o modifica ruta crítica. | AH5: Governance/Readiness | AI5: PM; PF | AJ5: No directo | AK5: scene_anchor | AL5: Actividad confirmada o reconstruida por usuario; no inferencia no confirmada. | AM5: B0↔B0.5; B0↔B1; B0↔B2 | AN5: Débil | AO5: S1; canal algedónico si no puede delimitarse | AP5: S1 | algedonic_channel | AQ5: No | AR5: flag de calidad narrativa; no diagnóstico | AS5: alta | AT5: SceneCanonicalRecord; EvidenceBundle; MDSB | AU5: GapObject / EvidenceInsufficiency | AV5: explicitly_carried_forward if unresolved | AW5: La actividad queda nombrada pero no reconocible. | AX5: 37dc8a474bc09c1b99f4aea59a66da464f0b197bde855f63936b3fdabb4ca77d
A6: 0.1.0 | B6: 1.0 | C6: B0_0_3 | D6: C1B0-005 | E6: 0 | F6: 5 | G6: 0.3 | H6: Bloque_0_Documento_Madre_Capa1_v2_1_EVE_rev4_redisenado_robusto.docx | I6: Versión del documento: 0.4 de trabajo | Rediseño controlado B0-UX-SEM-001 | Entrada robusta desde WorkMapIntake con actividad completa, parcial, no estructurada o mínima | Mantiene compatibilidad interna con scene_anchor_bundle. | J6: Fuente canónica de nodos | K6: Fuente final aprobada | L6: 15 | M6: active | N6: base_question | O6: base | P6: anclaje_semantico | Q6: ¿Con qué frecuencia haces esta actividad? | R6: Siempre | S6: ¿Con qué frecuencia haces esta actividad? | T6: Siempre | U6: Obligatoria | V6: activity_frequency_base / scene_frequency_base | X6: normal | Y6: FALSE | AA6: captured_user_evidence | AB6: captured_user_evidence | AC6: captured_user_evidence | AD6: captured_user_evidence | AE6: No aplica / captura directa | AF6: No inferir como captured_user_evidence; exigir confirmación si afecta ruta canónica. | AG6: Audit log requerido si se deriva, corrige, bloquea o modifica ruta crítica. | AH6: Governance/Readiness | AI6: PM; PF | AJ6: No directo | AK6: scene_anchor | AL6: Actividad confirmada o reconstruida por usuario; no inferencia no confirmada. | AM6: B0↔B0.5; B0↔B1; B0↔B2 | AN6: Débil | AO6: S1; canal algedónico si no puede delimitarse | AP6: S1 | algedonic_channel | AQ6: No | AR6: flag de calidad narrativa; no diagnóstico | AS6: alta | AT6: SceneCanonicalRecord; EvidenceBundle; MDSB | AU6: GapObject / EvidenceInsufficiency | AV6: explicitly_carried_forward if unresolved | AW6: Se reduce comparabilidad y capacidad de dimensionar recurrencia. | AX6: 55ba28dd4c594607abf1dcaa638f7464523208733c35f5d6284200c4b1c540e9
A7: 0.1.0 | B7: 1.0 | C7: B0_0_3a | D7: C1B0-006 | E7: 0 | F7: 6 | G7: 0.3a | H7: Bloque_0_Documento_Madre_Capa1_v2_1_EVE_rev4_redisenado_robusto.docx | I7: Versión del documento: 0.4 de trabajo | Rediseño controlado B0-UX-SEM-001 | Entrada robusta desde WorkMapIntake con actividad completa, parcial, no estructurada o mínima | Mantiene compatibilidad interna con scene_anchor_bundle. | J7: Fuente canónica de nodos | K7: Fuente final aprobada | L7: 16 | M7: active | N7: conditional_question | O7: condicional | P7: anclaje_semantico | Q7: Si cambia la frecuencia, ¿qué la hace más probable? | R7: Si 0.3 indica irregularidad, cierre, contingencia o estacionalidad | S7: Si cambia la frecuencia, ¿qué la hace más probable? | T7: Solo si aplica | U7: Obligatoria si 0.3 indica variable | V7: activity_frequency_pattern_hint | X7: normal | Y7: FALSE | AA7: captured_user_evidence | AB7: captured_user_evidence | AC7: captured_user_evidence | AD7: captured_user_evidence | AE7: No aplica / captura directa | AF7: No inferir como captured_user_evidence; exigir confirmación si afecta ruta canónica. | AG7: Audit log requerido si se deriva, corrige, bloquea o modifica ruta crítica. | AH7: Governance/Readiness | AI7: PM; PF | AJ7: No directo | AK7: scene_anchor | AL7: Actividad confirmada o reconstruida por usuario; no inferencia no confirmada. | AM7: B0↔B0.5; B0↔B1; B0↔B2 | AN7: Débil | AO7: S1; canal algedónico si no puede delimitarse | AP7: S1 | algedonic_channel | AQ7: No | AR7: flag de calidad narrativa; no diagnóstico | AS7: media | AT7: SceneCanonicalRecord; EvidenceBundle; MDSB | AU7: ReviewNote / non_blocking_flag | AV7: explicitly_carried_forward if unresolved | AW7: La irregularidad queda poco útil para recorrido posterior. | AX7: 91b30904d002034b1b65e4b4ca37217e1e76f7f432b1b720c41941569c10f480
A8: 0.1.0 | B8: 1.0 | C8: B0_0_4 | D8: C1B0-007 | E8: 0 | F8: 7 | G8: 0.4 | H8: Bloque_0_Documento_Madre_Capa1_v2_1_EVE_rev4_redisenado_robusto.docx | I8: Versión del documento: 0.4 de trabajo | Rediseño controlado B0-UX-SEM-001 | Entrada robusta desde WorkMapIntake con actividad completa, parcial, no estructurada o mínima | Mantiene compatibilidad interna con scene_anchor_bundle. | J8: Fuente canónica de nodos | K8: Fuente final aprobada | L8: 17 | M8: active | N8: base_question | O8: base | P8: anclaje_semantico | Q8: ¿En qué situación suele aparecer esta actividad? | R8: Siempre | S8: ¿En qué situación suele aparecer esta actividad? | T8: Siempre | U8: Obligatoria | V8: activity_typical_context / scene_typical_context | X8: normal | Y8: FALSE | AA8: captured_user_evidence | AB8: captured_user_evidence | AC8: captured_user_evidence | AD8: captured_user_evidence | AE8: No aplica / captura directa | AF8: No inferir como captured_user_evidence; exigir confirmación si afecta ruta canónica. | AG8: Audit log requerido si se deriva, corrige, bloquea o modifica ruta crítica. | AH8: Governance/Readiness | AI8: PM; PF | AJ8: No directo | AK8: scene_anchor | AL8: Actividad confirmada o reconstruida por usuario; no inferencia no confirmada. | AM8: B0↔B0.5; B0↔B1; B0↔B2 | AN8: Débil | AO8: S1; canal algedónico si no puede delimitarse | AP8: S1 | algedonic_channel | AQ8: No | AR8: flag de calidad narrativa; no diagnóstico | AS8: alta | AT8: SceneCanonicalRecord; EvidenceBundle; MDSB | AU8: GapObject / EvidenceInsufficiency | AV8: explicitly_carried_forward if unresolved | AW8: La actividad queda fuera de situación. | AX8: 8a8cd1da87faccf070eef8dd9a38d7c67fd8b5f25d73bd2fdcf170bd06f8562d
A9: 0.1.0 | B9: 1.0 | C9: B0_0_5_actor_scope | D9: C1B0-008 | E9: 0 | F9: 8 | G9: 0.5_actor_scope | H9: Bloque_0_Documento_Madre_Capa1_v2_1_EVE_rev4_redisenado_robusto.docx | I9: Versión del documento: 0.4 de trabajo | Rediseño controlado B0-UX-SEM-001 | Entrada robusta desde WorkMapIntake con actividad completa, parcial, no estructurada o mínima | Mantiene compatibilidad interna con scene_anchor_bundle. | J9: Fuente canónica de nodos | K9: Fuente final aprobada | L9: 18 | M9: active | N9: base_question | O9: base | P9: anclaje_semantico | Q9: ¿Quién la hace normalmente o sobre quién recae directamente? | R9: Siempre; puede prellenarse desde responsabilidad declarada | S9: ¿Quién la hace normalmente o sobre quién recae directamente? | T9: Siempre | U9: Obligatoria | V9: activity_primary_actor_scope / scene_primary_actor_scope | X9: normal | Y9: FALSE | AA9: captured_user_evidence or declared_confirmed_context | AB9: declared_confirmed_context | captured_user_evidence | AC9: captured_user_evidence or declared_confirmed_context | AD9: declared_confirmed_context | captured_user_evidence | AE9: No aplica / captura directa | AF9: No inferir como captured_user_evidence; exigir confirmación si afecta ruta canónica. | AG9: Audit log requerido si se deriva, corrige, bloquea o modifica ruta crítica. | AH9: Governance/Readiness | AI9: PM; PF | AJ9: No directo | AK9: scene_anchor | AL9: Actividad confirmada o reconstruida por usuario; no inferencia no confirmada. | AM9: B0↔B0.5; B0↔B1; B0↔B2 | AN9: Débil | AO9: S1; canal algedónico si no puede delimitarse | AP9: S1 | algedonic_channel | AQ9: No | AR9: flag de calidad narrativa; no diagnóstico | AS9: media | AT9: SceneCanonicalRecord; EvidenceBundle; MDSB | AU9: ReviewNote / non_blocking_flag | AV9: explicitly_carried_forward if unresolved | AW9: La actividad pierde punto de observación inmediato. | AX9: 09f2253cf28c390e354d1e17cc3ffdb040c09aa225243f80b0f58e0ce52dab20
A10: 0.1.0 | B10: 1.0 | C10: B0_0_6 | D10: C1B0-009 | E10: 0 | F10: 9 | G10: 0.6 | H10: Bloque_0_Documento_Madre_Capa1_v2_1_EVE_rev4_redisenado_robusto.docx | I10: Versión del documento: 0.4 de trabajo | Rediseño controlado B0-UX-SEM-001 | Entrada robusta desde WorkMapIntake con actividad completa, parcial, no estructurada o mínima | Mantiene compatibilidad interna con scene_anchor_bundle. | J10: Fuente canónica de nodos | K10: Fuente final aprobada | L10: 19 | M10: active | N10: confirmation_card | O10: confirmacion_asistida | P10: anclaje_semantico | Q10: ¿Qué recibes, ves o necesitas para empezar esta actividad? | R10: Siempre; puede sugerirse desde Insumo / Objeto | S10: ¿Qué recibes, ves o necesitas para empezar esta actividad? | T10: Siempre | U10: Obligatoria | V10: activity_start_condition_hint / scene_boundary_start_hint | X10: normal | Y10: FALSE | AA10: captured_user_evidence or user_confirmed_suggestion | AB10: user_confirmed_suggestion | captured_user_evidence | AC10: captured_user_evidence or user_confirmed_suggestion | AD10: user_confirmed_suggestion | captured_user_evidence | AE10: Confirmar siempre | AF10: No inferir como captured_user_evidence; exigir confirmación si afecta ruta canónica. | AG10: Audit log requerido si se deriva, corrige, bloquea o modifica ruta crítica. | AH10: Governance/Readiness | AI10: PM; PF | AJ10: No directo | AK10: scene_anchor | AL10: Actividad confirmada o reconstruida por usuario; no inferencia no confirmada. | AM10: B0↔B0.5; B0↔B1; B0↔B2 | AN10: Débil | AO10: S1; canal algedónico si no puede delimitarse | AP10: S1 | algedonic_channel | AQ10: No | AR10: flag de calidad narrativa; no diagnóstico | AS10: alta | AT10: SceneCanonicalRecord; EvidenceBundle; MDSB | AU10: GapObject / EvidenceInsufficiency | AV10: explicitly_carried_forward if unresolved | AW10: No hay entrada reconocible para recorrer la actividad. | AX10: 12e08bba5a80091573872d67ce6974cac3893b8b4ef953009f5296dd0c0d3446
A11: 0.1.0 | B11: 1.0 | C11: B0_0_7 | D11: C1B0-010 | E11: 0 | F11: 10 | G11: 0.7 | H11: Bloque_0_Documento_Madre_Capa1_v2_1_EVE_rev4_redisenado_robusto.docx | I11: Versión del documento: 0.4 de trabajo | Rediseño controlado B0-UX-SEM-001 | Entrada robusta desde WorkMapIntake con actividad completa, parcial, no estructurada o mínima | Mantiene compatibilidad interna con scene_anchor_bundle. | J11: Fuente canónica de nodos | K11: Fuente final aprobada | L11: 20 | M11: active | N11: confirmation_card | O11: confirmacion_asistida | P11: anclaje_semantico | Q11: ¿Qué queda listo para darla por terminada? | R11: Siempre; puede sugerirse desde Producto / Salida | S11: ¿Qué queda listo para darla por terminada? | T11: Siempre | U11: Obligatoria | V11: activity_end_result_hint / scene_boundary_end_hint | X11: normal | Y11: FALSE | AA11: captured_user_evidence or user_confirmed_suggestion | AB11: user_confirmed_suggestion | captured_user_evidence | AC11: captured_user_evidence or user_confirmed_suggestion | AD11: user_confirmed_suggestion | captured_user_evidence | AE11: Confirmar siempre | AF11: No inferir como captured_user_evidence; exigir confirmación si afecta ruta canónica. | AG11: Audit log requerido si se deriva, corrige, bloquea o modifica ruta crítica. | AH11: Governance/Readiness | AI11: PM; PF | AJ11: No directo | AK11: scene_anchor | AL11: Actividad confirmada o reconstruida por usuario; no inferencia no confirmada. | AM11: B0↔B0.5; B0↔B1; B0↔B2 | AN11: Débil | AO11: S1; canal algedónico si no puede delimitarse | AP11: S1 | algedonic_channel | AQ11: No | AR11: flag de calidad narrativa; no diagnóstico | AS11: media | AT11: SceneCanonicalRecord; EvidenceBundle; MDSB | AU11: ReviewNote / non_blocking_flag | AV11: explicitly_carried_forward if unresolved | AW11: No hay salida mínima para distinguir esta actividad de la siguiente. | AX11: a2d1fc2c7fb07fee53e814f37d489473d6e27bfebd3880385c3ae00da6da662a
A12: 0.1.0 | B12: 1.0 | C12: B0_0_8 | D12: C1B0-011 | E12: 0 | F12: 11 | G12: 0.8 | H12: Bloque_0_Documento_Madre_Capa1_v2_1_EVE_rev4_redisenado_robusto.docx | I12: Versión del documento: 0.4 de trabajo | Rediseño controlado B0-UX-SEM-001 | Entrada robusta desde WorkMapIntake con actividad completa, parcial, no estructurada o mínima | Mantiene compatibilidad interna con scene_anchor_bundle. | J12: Fuente canónica de nodos | K12: Fuente final aprobada | L12: 21 | M12: active | N12: base_question | O12: base | P12: anclaje_semantico | Q12: ¿La haces casi siempre igual o cambia según el caso? | R12: Siempre | S12: ¿La haces casi siempre igual o cambia según el caso? | T12: Siempre | U12: Obligatoria | V12: activity_variation_mode / scene_variation_mode | X12: normal | Y12: FALSE | AA12: captured_user_evidence | AB12: captured_user_evidence | AC12: captured_user_evidence | AD12: captured_user_evidence | AE12: No aplica / captura directa | AF12: No inferir como captured_user_evidence; exigir confirmación si afecta ruta canónica. | AG12: Audit log requerido si se deriva, corrige, bloquea o modifica ruta crítica. | AH12: Governance/Readiness | AI12: PM; PF | AJ12: No directo | AK12: scene_anchor | AL12: Actividad confirmada o reconstruida por usuario; no inferencia no confirmada. | AM12: B0↔B0.5; B0↔B1; B0↔B2 | AN12: Débil | AO12: S1; canal algedónico si no puede delimitarse | AP12: S1 | algedonic_channel | AQ12: No | AR12: flag de calidad narrativa; no diagnóstico | AS12: media | AT12: SceneCanonicalRecord; EvidenceBundle; MDSB | AU12: ReviewNote / non_blocking_flag | AV12: explicitly_carried_forward if unresolved | AW12: Se aplana variedad operativa que puede ser crítica más adelante. | AX12: 2816d6e12046cf045a2c038825c418e082bbf9dc8c5c61e3e7b1b7d435db1248
A13: 0.1.0 | B13: 1.0 | C13: B0_0_8a | D13: C1B0-012 | E13: 0 | F13: 12 | G13: 0.8a | H13: Bloque_0_Documento_Madre_Capa1_v2_1_EVE_rev4_redisenado_robusto.docx | I13: Versión del documento: 0.4 de trabajo | Rediseño controlado B0-UX-SEM-001 | Entrada robusta desde WorkMapIntake con actividad completa, parcial, no estructurada o mínima | Mantiene compatibilidad interna con scene_anchor_bundle. | J13: Fuente canónica de nodos | K13: Fuente final aprobada | L13: 22 | M13: active | N13: conditional_question | O13: condicional | P13: anclaje_semantico | Q13: ¿Cuál es el cambio o caso especial más común? | R13: Si 0.8 indica variación relevante o alta | S13: ¿Cuál es el cambio o caso especial más común? | T13: Solo si aplica | U13: Obligatoria si 0.8 indica variación relevante o alta | V13: activity_exception_signature / scene_exception_signature | X13: normal | Y13: FALSE | AA13: captured_user_evidence | AB13: captured_user_evidence | AC13: captured_user_evidence | AD13: captured_user_evidence | AE13: No aplica / captura directa | AF13: No inferir como captured_user_evidence; exigir confirmación si afecta ruta canónica. | AG13: Audit log requerido si se deriva, corrige, bloquea o modifica ruta crítica. | AH13: Governance/Readiness | AI13: PM; PF | AJ13: No directo | AK13: scene_anchor | AL13: Actividad confirmada o reconstruida por usuario; no inferencia no confirmada. | AM13: B0↔B0.5; B0↔B1; B0↔B2 | AN13: Débil | AO13: S1; canal algedónico si no puede delimitarse | AP13: S1 | algedonic_channel | AQ13: No | AR13: flag de calidad narrativa; no diagnóstico | AS13: media | AT13: SceneCanonicalRecord; EvidenceBundle; MDSB | AU13: ReviewNote / non_blocking_flag | AV13: explicitly_carried_forward if unresolved | AW13: La variación declarada queda sin forma operativa. | AX13: ccbc4a1d92413e0478bca3238027a457ccbc5741a57c6bcb7e22f72c77fdd779
A14: 0.1.0 | B14: 1.0 | C14: B0_0_A | D14: C1B0-013 | E14: 0 | F14: 13 | G14: 0.A | H14: Bloque_0_Documento_Madre_Capa1_v2_1_EVE_rev4_redisenado_robusto.docx | I14: Versión del documento: 0.4 de trabajo | Rediseño controlado B0-UX-SEM-001 | Entrada robusta desde WorkMapIntake con actividad completa, parcial, no estructurada o mínima | Mantiene compatibilidad interna con scene_anchor_bundle. | J14: Fuente canónica de nodos | K14: Fuente final aprobada | L14: 23 | M14: active | N14: clarification_node | O14: aclaracion | P14: anclaje_semantico | Q14: El nombre suena amplio. ¿Qué distingue esta actividad de otras parecidas? | R14: Si hay genericidad | S14: El nombre suena amplio. ¿Qué distingue esta actividad de otras parecidas? | T14: Solo por flag de genericidad | U14: Obligatoria si hay genericidad | V14: activity_name_disambiguation | X14: normal | Y14: FALSE | AA14: clarification | AB14: clarification | AC14: clarification | AD14: clarification | AE14: No aplica / captura directa | AF14: No inferir como captured_user_evidence; exigir confirmación si afecta ruta canónica. | AG14: Audit log requerido si se deriva, corrige, bloquea o modifica ruta crítica. | AH14: Governance/Readiness | AI14: PM; PF | AJ14: No directo | AK14: scene_anchor | AL14: Actividad confirmada o reconstruida por usuario; no inferencia no confirmada. | AM14: B0↔B0.5; B0↔B1; B0↔B2 | AN14: Débil | AO14: S1; canal algedónico si no puede delimitarse | AP14: S1 | algedonic_channel | AQ14: No | AR14: flag de calidad narrativa; no diagnóstico | AS14: alta | AT14: SceneCanonicalRecord; EvidenceBundle; MDSB | AU14: GapObject / EvidenceInsufficiency | AV14: explicitly_carried_forward if unresolved | AW14: Actividades distintas pueden colapsar bajo una misma etiqueta. | AX14: b1a0fb877a17f24b991f4f70c8cdc5b222057adc5a3e44c17350629fe7fa579d
A15: 0.1.0 | B15: 1.0 | C15: B0_0_B | D15: C1B0-014 | E15: 0 | F15: 14 | G15: 0.B | H15: Bloque_0_Documento_Madre_Capa1_v2_1_EVE_rev4_redisenado_robusto.docx | I15: Versión del documento: 0.4 de trabajo | Rediseño controlado B0-UX-SEM-001 | Entrada robusta desde WorkMapIntake con actividad completa, parcial, no estructurada o mínima | Mantiene compatibilidad interna con scene_anchor_bundle. | J15: Fuente canónica de nodos | K15: Fuente final aprobada | L15: 24 | M15: active | N15: clarification_node | O15: aclaracion | P15: anclaje_semantico | Q15: Parece que el inicio y el cierre se mezclan. Completa: empieza cuando ___ y termina cuando ___. | R15: Si 0.6 y 0.7 no delimitan | S15: Parece que el inicio y el cierre se mezclan. Completa: empieza cuando ___ y termina cuando ___. | T15: Solo por flag de frontera | U15: Obligatoria si hay frontera difusa | V15: activity_boundary_clarification | X15: normal | Y15: FALSE | AA15: clarification | AB15: clarification | AC15: clarification | AD15: clarification | AE15: No aplica / captura directa | AF15: No inferir como captured_user_evidence; exigir confirmación si afecta ruta canónica. | AG15: Audit log requerido si se deriva, corrige, bloquea o modifica ruta crítica. | AH15: Governance/Readiness | AI15: PM; PF | AJ15: No directo | AK15: scene_anchor | AL15: Actividad confirmada o reconstruida por usuario; no inferencia no confirmada. | AM15: B0↔B0.5; B0↔B1; B0↔B2 | AN15: Débil | AO15: S1; canal algedónico si no puede delimitarse | AP15: S1 | algedonic_channel | AQ15: No | AR15: flag de calidad narrativa; no diagnóstico | AS15: alta | AT15: SceneCanonicalRecord; EvidenceBundle; MDSB | AU15: GapObject / EvidenceInsufficiency | AV15: explicitly_carried_forward if unresolved | AW15: La actividad no puede recorrerse causalmente. | AX15: 2cae02b6af9f8864b6b8a245aaea61977796b82c1d6dba9ef9476630e49be434
A16: 0.1.0 | B16: 1.0 | C16: B0_0_C | D16: C1B0-015 | E16: 0 | F16: 15 | G16: 0.C | H16: Bloque_0_Documento_Madre_Capa1_v2_1_EVE_rev4_redisenado_robusto.docx | I16: Versión del documento: 0.4 de trabajo | Rediseño controlado B0-UX-SEM-001 | Entrada robusta desde WorkMapIntake con actividad completa, parcial, no estructurada o mínima | Mantiene compatibilidad interna con scene_anchor_bundle. | J16: Fuente canónica de nodos | K16: Fuente final aprobada | L16: 25 | M16: active | N16: clarification_node | O16: aclaracion | P16: anclaje_semantico | Q16: Esta descripción parece muy grande o muy pequeña. ¿Qué parte concreta conviene revisar de inicio a fin? | R16: Si la escala no es recorrible | S16: Esta descripción parece muy grande o muy pequeña. ¿Qué parte concreta conviene revisar de inicio a fin? | T16: Solo por flag de escala | U16: Obligatoria si la escala no es recorrible | V16: activity_scale_adjustment | X16: normal | Y16: FALSE | AA16: clarification | AB16: clarification | AC16: clarification | AD16: clarification | AE16: No aplica / captura directa | AF16: No inferir como captured_user_evidence; exigir confirmación si afecta ruta canónica. | AG16: Audit log requerido si se deriva, corrige, bloquea o modifica ruta crítica. | AH16: Governance/Readiness | AI16: PM; PF | AJ16: No directo | AK16: scene_anchor | AL16: Actividad confirmada o reconstruida por usuario; no inferencia no confirmada. | AM16: B0↔B0.5; B0↔B1; B0↔B2 | AN16: Débil | AO16: S1; canal algedónico si no puede delimitarse | AP16: S1 | algedonic_channel | AQ16: No | AR16: flag de calidad narrativa; no diagnóstico | AS16: alta | AT16: SceneCanonicalRecord; EvidenceBundle; MDSB | AU16: GapObject / EvidenceInsufficiency | AV16: explicitly_carried_forward if unresolved | AW16: La actividad no será comparable ni transducible. | AX16: 43b44896a0e059416fcc77f1d18747378f32d271d29ec545b75b3a06300c199f
A17: 0.1.0 | B17: 1.0 | C17: B0_0_D | D17: C1B0-016 | E17: 0 | F17: 16 | G17: 0.D | H17: Bloque_0_Documento_Madre_Capa1_v2_1_EVE_rev4_redisenado_robusto.docx | I17: Versión del documento: 0.4 de trabajo | Rediseño controlado B0-UX-SEM-001 | Entrada robusta desde WorkMapIntake con actividad completa, parcial, no estructurada o mínima | Mantiene compatibilidad interna con scene_anchor_bundle. | J17: Fuente canónica de nodos | K17: Fuente final aprobada | L17: 26 | M17: active | N17: clarification_node | O17: aclaracion | P17: anclaje_semantico | Q17: La estructura parece incompleta. ¿Qué falta: sobre qué trabajas, con qué criterio o qué queda listo? | R17: Si faltan componentes semánticos críticos | S17: La estructura parece incompleta. ¿Qué falta: sobre qué trabajas, con qué criterio o qué queda listo? | T17: Solo por semantic_component_gap_flag o partial_structure_entry_mode | U17: Obligatoria si falta componente semántico crítico y todavía puede completarse sin forzar una inferencia | V17: activity_semantic_completion / semantic_gap_unresolved | W17: CR-B0-WorkMapIntake-semantic-entry | X17: ruta_crítica | Y17: TRUE | Z17: CR-B0-WorkMapIntake-semantic-entry | AA17: clarification / user_corrected_evidence | AB17: user_corrected_evidence | clarification | AC17: clarification / user_corrected_evidence | AD17: user_corrected_evidence | clarification | AE17: No aplica / captura directa | AF17: No inferir como captured_user_evidence; exigir confirmación si afecta ruta canónica. | AG17: Audit log requerido si se deriva, corrige, bloquea o modifica ruta crítica. | AH17: Governance/Readiness | AI17: PM; PF | AJ17: No directo | AK17: scene_anchor | AL17: Actividad confirmada o reconstruida por usuario; no inferencia no confirmada. | AM17: B0↔B0.5; B0↔B1; B0↔B2 | AN17: Débil | AO17: S1; canal algedónico si no puede delimitarse | AP17: S1 | algedonic_channel | AQ17: No | AR17: flag de calidad narrativa; no diagnóstico | AS17: bloqueante/ruta_crítica | AT17: SceneCanonicalRecord; EvidenceBundle; MDSB | AU17: CanonicalRouteException | AV17: blocked_or_reentry_required | AW17: La IA puede inferir demasiado; el usuario puede avanzar con una frase incompleta siempre que el gap quede visible y Bloque 0 capture mínimos de anclaje. | AX17: 897e05d6cd56fe81e5c5e9df5937e4c9b6ef81c44f987a440e3d72471d9f057d
A18: 0.1.0 | B18: 1.0 | C18: B0_block0_entry_control | D18: C1B0-017 | E18: 0 | F18: 17 | G18: block0_entry_control | H18: Bloque_0_Documento_Madre_Capa1_v2_1_EVE_rev4_redisenado_robusto.docx | I18: Versión del documento: 0.4 de trabajo | Rediseño controlado B0-UX-SEM-001 | Entrada robusta desde WorkMapIntake con actividad completa, parcial, no estructurada o mínima | Mantiene compatibilidad interna con scene_anchor_bundle. | J18: Fuente canónica de nodos | K18: Fuente final aprobada | L18: 34 | M18: active | N18: confirmation_card | O18: confirmacion_asistida | P18: anclaje_semantico | Q18: semantic_review_status, semantic_review_attempt_count, semantic_assistance_failed_flag, block0_entry_mode. | S18: semantic_review_status, semantic_review_attempt_count, semantic_assistance_failed_flag, block0_entry_mode. | X18: sin_variable_directa | Y18: TRUE | Z18: CR-B0-WorkMapIntake-semantic-entry | AB18: no_epistemic_status | AD18: no_epistemic_status | AE18: Confirmar siempre | AF18: No inferir como captured_user_evidence; exigir confirmación si afecta ruta canónica. | AG18: Audit log requerido si se deriva, corrige, bloquea o modifica ruta crítica. | AH18: Governance/Readiness | AI18: PM; PF | AJ18: No directo | AK18: scene_anchor | AL18: Actividad confirmada o reconstruida por usuario; no inferencia no confirmada. | AM18: B0↔B0.5; B0↔B1; B0↔B2 | AN18: Débil | AO18: S1; canal algedónico si no puede delimitarse | AP18: S1 | algedonic_channel | AQ18: No | AR18: flag de calidad narrativa; no diagnóstico | AS18: media | AT18: SceneCanonicalRecord; EvidenceBundle; MDSB | AU18: ReviewNote / non_blocking_flag | AV18: explicitly_carried_forward if unresolved | AX18: b651d7cb23c772c01fc68516f8597507183d5cd50537256d9b738a1b1e7270f2
A19: 0.1.0 | B19: 1.0 | C19: B0_5_0_5_1 | D19: C1B0_5-001 | E19: 0.5 | F19: 1 | G19: 0.5.1 | H19: Bloque_0_5_Documento_Madre_Capa1_v2_1_EVE.docx | I19: Versión del documento: 0.1 de trabajo | Base estructural: Diseno_Formal_Capa1_v2_1_Unificado | Base de redacción operativa: Marco de Trabajo y Catálogo de Preguntas v2.1 - Bloque 0.5 (Encuadre) | J19: Fuente canónica de nodos | K19: Fuente final aprobada | L19: 3 | M19: active | N19: base_question | O19: base | P19: encuadre_sistemico | Q19: Independientemente de a quién le entregues tu trabajo directamente, ¿quién es la persona, área o actor que finalmente se beneficia si esta actividad sale bien? | R19: Siempre | S19: Independientemente de a quién le entregues tu trabajo directamente, ¿quién es la persona, área o actor que finalmente se beneficia si esta actividad sale bien? | T19: Siempre | U19: Obligatoria para toda escena profunda y abreviada que pase por Bloque 0.5 | V19: beneficiario_final_0_5_1 + scene_functional_client (derivable) | X19: normal | Y19: FALSE | AA19: capturado (captured_user_evidence) | AB19: captured_user_evidence | AC19: capturado (captured_user_evidence) | AD19: captured_user_evidence | AE19: No aplica / captura directa | AF19: No inferir como captured_user_evidence; exigir confirmación si afecta ruta canónica. | AG19: Audit log requerido si se deriva, corrige, bloquea o modifica ruta crítica. | AH19: PM | AI19: PF; MoC | AJ19: Condicional | AK19: cliente_funcional_candidate | AL19: Representa ubicación sistémica de la actividad, no receptor inmediato solamente. | AM19: PM↔PF; PM↔MoC | AN19: Sí | AO19: S1; S2; S3; S4; S5 | AP19: S1 | S2 | S3 | S4 | S5 | AQ19: No directo | AR19: preparación; no diagnóstico | AS19: alta | AT19: SCR; EvidenceBundle; MDSB; Inventory PM candidates | AU19: GapObject / EvidenceInsufficiency | AV19: explicitly_carried_forward if unresolved | AW19: La escena queda sin conexión explícita con el valor que produce en el sistema y se vuelve fácil confundirla con una tarea autosuficiente. | AX19: 1bbcf0764bd2357e9458218bafdf2b01838b5915898b56e2ad5bf7f6bca54fcc
A20: 0.1.0 | B20: 1.0 | C20: B0_5_0_5_1a | D20: C1B0_5-002 | E20: 0.5 | F20: 2 | G20: 0.5.1a | H20: Bloque_0_5_Documento_Madre_Capa1_v2_1_EVE.docx | I20: Versión del documento: 0.1 de trabajo | Base estructural: Diseno_Formal_Capa1_v2_1_Unificado | Base de redacción operativa: Marco de Trabajo y Catálogo de Preguntas v2.1 - Bloque 0.5 (Encuadre) | J20: Fuente canónica de nodos | K20: Fuente final aprobada | L20: 4 | M20: active | N20: base_question | O20: base | P20: encuadre_sistemico | Q20: Independientemente de a quién le entregues tu trabajo directamente, ¿quién es la persona, área o actor que finalmente sufre si esta actividad sale mal o no sale? | R20: Siempre | S20: Independientemente de a quién le entregues tu trabajo directamente, ¿quién es la persona, área o actor que finalmente sufre si esta actividad sale mal o no sale? | T20: Siempre | U20: Obligatoria | V20: afectado_final_0_5_1a | X20: normal | Y20: FALSE | AA20: capturado (captured_user_evidence) | AB20: captured_user_evidence | AC20: capturado (captured_user_evidence) | AD20: captured_user_evidence | AE20: No aplica / captura directa | AF20: No inferir como captured_user_evidence; exigir confirmación si afecta ruta canónica. | AG20: Audit log requerido si se deriva, corrige, bloquea o modifica ruta crítica. | AH20: PM | AI20: PF; MoC | AJ20: Condicional | AK20: cliente_funcional_candidate | AL20: Representa ubicación sistémica de la actividad, no receptor inmediato solamente. | AM20: PM↔PF; PM↔MoC | AN20: Sí | AO20: S1; S2; S3; S4; S5 | AP20: S1 | S2 | S3 | S4 | S5 | AQ20: No directo | AR20: preparación; no diagnóstico | AS20: alta | AT20: SCR; EvidenceBundle; MDSB; Inventory PM candidates | AU20: GapObject / EvidenceInsufficiency | AV20: explicitly_carried_forward if unresolved | AW20: Se pierde la posibilidad de distinguir creación de valor de absorción de daño, y eso aplana la escena de una forma metodológicamente peligrosa. | AX20: 031c45e345db6d13558fe5e67fb5f0db10d77c65ca595ccd84a94b8754f339d0
A21: 0.1.0 | B21: 1.0 | C21: B0_5_0_5_1_rel | D21: C1B0_5-003 | E21: 0.5 | F21: 3 | G21: 0.5.1_rel | H21: Bloque_0_5_Documento_Madre_Capa1_v2_1_EVE.docx | I21: Versión del documento: 0.1 de trabajo | Base estructural: Diseno_Formal_Capa1_v2_1_Unificado | Base de redacción operativa: Marco de Trabajo y Catálogo de Preguntas v2.1 - Bloque 0.5 (Encuadre) | J21: Fuente canónica de nodos | K21: Fuente final aprobada | L21: 5 | M21: active | N21: clarification_node | O21: aclaracion | P21: encuadre_sistemico | Q21: ¿El que se beneficia cuando esto sale bien y el que sufre cuando esto sale mal son el mismo actor o son distintos? | R21: Después de 0.5.1 y 0.5.1a | S21: ¿El que se beneficia cuando esto sale bien y el que sufre cuando esto sale mal son el mismo actor o son distintos? | T21: Siempre después de 0.5.1 y 0.5.1a | U21: Obligatoria, una vez capturados 0.5.1 y 0.5.1a | V21: relacion_beneficiario_afectado_0_5_1_rel | X21: normal | Y21: FALSE | AA21: capturado (captured_user_evidence) | AB21: captured_user_evidence | AC21: capturado (captured_user_evidence) | AD21: captured_user_evidence | AE21: No aplica / captura directa | AF21: No inferir como captured_user_evidence; exigir confirmación si afecta ruta canónica. | AG21: Audit log requerido si se deriva, corrige, bloquea o modifica ruta crítica. | AH21: PM | AI21: PF; MoC | AJ21: Condicional | AK21: cliente_funcional_candidate | AL21: Representa ubicación sistémica de la actividad, no receptor inmediato solamente. | AM21: PM↔PF; PM↔MoC | AN21: Sí | AO21: S1; S2; S3; S4; S5 | AP21: S1 | S2 | S3 | S4 | S5 | AQ21: No directo | AR21: preparación; no diagnóstico | AS21: alta | AT21: SCR; EvidenceBundle; MDSB; Inventory PM candidates | AU21: GapObject / EvidenceInsufficiency | AV21: explicitly_carried_forward if unresolved | AW21: Queda sin explicitar una diferencia estructural relevante entre quién recibe el valor y quién absorbe el daño. | AX21: 4bb8d5f3cf8bd0e2fe7678a9fb57c3ecc85589069741a0ef1afb70cb4b26867c
A22: 0.1.0 | B22: 1.0 | C22: B0_5_0_5_1b | D22: C1B0_5-004 | E22: 0.5 | F22: 4 | G22: 0.5.1b | H22: Bloque_0_5_Documento_Madre_Capa1_v2_1_EVE.docx | I22: Versión del documento: 0.1 de trabajo | Base estructural: Diseno_Formal_Capa1_v2_1_Unificado | Base de redacción operativa: Marco de Trabajo y Catálogo de Preguntas v2.1 - Bloque 0.5 (Encuadre) | J22: Fuente canónica de nodos | K22: Fuente final aprobada | L22: 6 | M22: active | N22: conditional_question | O22: condicional | P22: encuadre_sistemico | Q22: Si son distintos, ¿quién recibe primero el beneficio y quién absorbe primero el daño cuando falla? | R22: Si 0.5.1_rel = Son actores distintos | S22: Si son distintos, ¿quién recibe primero el beneficio y quién absorbe primero el daño cuando falla? | T22: Solo si 0.5.1_rel = Son actores distintos | U22: Condicional | V22: beneficio_vs_dano_distribucion_0_5_1b | X22: normal | Y22: FALSE | AA22: capturado / aclarado (clarification) | AB22: clarification | captured_user_evidence | AC22: capturado / aclarado (clarification) | AD22: clarification | captured_user_evidence | AE22: No aplica / captura directa | AF22: No inferir como captured_user_evidence; exigir confirmación si afecta ruta canónica. | AG22: Audit log requerido si se deriva, corrige, bloquea o modifica ruta crítica. | AH22: PM | AI22: PF; MoC | AJ22: Condicional | AK22: cliente_funcional_candidate | AL22: Representa ubicación sistémica de la actividad, no receptor inmediato solamente. | AM22: PM↔PF; PM↔MoC | AN22: Sí | AO22: S1; S2; S3; S4; S5 | AP22: S1 | S2 | S3 | S4 | S5 | AQ22: No directo | AR22: preparación; no diagnóstico | AS22: media | AT22: SCR; EvidenceBundle; MDSB; Inventory PM candidates | AU22: ReviewNote / non_blocking_flag | AV22: explicitly_carried_forward if unresolved | AW22: Cuando valor y daño no coinciden, la escena queda simplificada en exceso y se pierde un desplazamiento sistémico importante. | AX22: 62da84c4bfb23771c3bcbbefd8dbc9fd6fcb77b1a7073a2331656b846ec48609
A23: 0.1.0 | B23: 1.0 | C23: B0_5_0_5_1c | D23: C1B0_5-005 | E23: 0.5 | F23: 5 | G23: 0.5.1c | H23: Bloque_0_5_Documento_Madre_Capa1_v2_1_EVE.docx | I23: Versión del documento: 0.1 de trabajo | Base estructural: Diseno_Formal_Capa1_v2_1_Unificado | Base de redacción operativa: Marco de Trabajo y Catálogo de Preguntas v2.1 - Bloque 0.5 (Encuadre) | J23: Fuente canónica de nodos | K23: Fuente final aprobada | L23: 7 | M23: active | N23: base_question | O23: base | P23: encuadre_sistemico | Q23: ¿Qué tan claro tienes quién se beneficia realmente de que esta actividad salga bien? | R23: Siempre | S23: ¿Qué tan claro tienes quién se beneficia realmente de que esta actividad salga bien? | T23: Siempre | U23: Obligatoria | V23: claridad_beneficiario_0_5_1c | X23: normal | Y23: FALSE | AA23: readiness_marker | AB23: readiness_marker | AC23: captured_user_self_assessment | AD23: captured_user_self_assessment | AE23: No aplica / captura directa | AF23: No inferir como captured_user_evidence; exigir confirmación si afecta ruta canónica. | AG23: Audit log requerido si se deriva, corrige, bloquea o modifica ruta crítica. | AH23: PM | AI23: PF; MoC | AJ23: Condicional | AK23: cliente_funcional_candidate | AL23: Representa ubicación sistémica de la actividad, no receptor inmediato solamente. | AM23: PM↔PF; PM↔MoC | AN23: Sí | AO23: S1; S2; S3; S4; S5 | AP23: S1 | S2 | S3 | S4 | S5 | AQ23: No directo | AR23: preparación; no diagnóstico | AS23: alta | AT23: SCR; EvidenceBundle; MDSB; Inventory PM candidates | AU23: GapObject / EvidenceInsufficiency | AV23: explicitly_carried_forward if unresolved | AW23: El sistema no puede distinguir ausencia de problema de ausencia de claridad. | AX23: 18b3da8c32601f8dbf8e36764f9dffb1707c7bfed89b6a8c0382b63e225c241e
A24: 0.1.0 | B24: 1.0 | C24: B0_5_0_5_1d | D24: C1B0_5-006 | E24: 0.5 | F24: 6 | G24: 0.5.1d | H24: Bloque_0_5_Documento_Madre_Capa1_v2_1_EVE.docx | I24: Versión del documento: 0.1 de trabajo | Base estructural: Diseno_Formal_Capa1_v2_1_Unificado | Base de redacción operativa: Marco de Trabajo y Catálogo de Preguntas v2.1 - Bloque 0.5 (Encuadre) | J24: Fuente canónica de nodos | K24: Fuente final aprobada | L24: 8 | M24: active | N24: base_question | O24: base | P24: encuadre_sistemico | Q24: ¿Qué tan claro tienes quién sufre realmente si esta actividad sale mal? | R24: Siempre | S24: ¿Qué tan claro tienes quién sufre realmente si esta actividad sale mal? | T24: Siempre | U24: Obligatoria | V24: claridad_afectado_0_5_1d | X24: normal | Y24: FALSE | AA24: readiness_marker | AB24: readiness_marker | AC24: captured_user_self_assessment | AD24: captured_user_self_assessment | AE24: No aplica / captura directa | AF24: No inferir como captured_user_evidence; exigir confirmación si afecta ruta canónica. | AG24: Audit log requerido si se deriva, corrige, bloquea o modifica ruta crítica. | AH24: PM | AI24: PF; MoC | AJ24: Condicional | AK24: cliente_funcional_candidate | AL24: Representa ubicación sistémica de la actividad, no receptor inmediato solamente. | AM24: PM↔PF; PM↔MoC | AN24: Sí | AO24: S1; S2; S3; S4; S5 | AP24: S1 | S2 | S3 | S4 | S5 | AQ24: No directo | AR24: preparación; no diagnóstico | AS24: alta | AT24: SCR; EvidenceBundle; MDSB; Inventory PM candidates | AU24: GapObject / EvidenceInsufficiency | AV24: explicitly_carried_forward if unresolved | AW24: Se pierde una señal importante sobre la calidad epistemológica de la respuesta. | AX24: 47c3bdfb456d56412c32d13235e49c84d0e2657fc4646553005107b4eaffd20c
A25: 0.1.0 | B25: 1.0 | C25: B0_5_0_5_2 | D25: C1B0_5-007 | E25: 0.5 | F25: 7 | G25: 0.5.2 | H25: Bloque_0_5_Documento_Madre_Capa1_v2_1_EVE.docx | I25: Versión del documento: 0.1 de trabajo | Base estructural: Diseno_Formal_Capa1_v2_1_Unificado | Base de redacción operativa: Marco de Trabajo y Catálogo de Preguntas v2.1 - Bloque 0.5 (Encuadre) | J25: Fuente canónica de nodos | K25: Fuente final aprobada | L25: 9 | M25: active | N25: base_question | O25: base | P25: encuadre_sistemico | Q25: ¿A qué gran proceso de la empresa pertenece esta actividad? | R25: Siempre | S25: ¿A qué gran proceso de la empresa pertenece esta actividad? | T25: Siempre | U25: Obligatoria | V25: scene_macro_process | X25: normal | Y25: FALSE | AA25: capturado (captured_user_evidence) | AB25: captured_user_evidence | AC25: capturado (captured_user_evidence) | AD25: captured_user_evidence | AE25: No aplica / captura directa | AF25: No inferir como captured_user_evidence; exigir confirmación si afecta ruta canónica. | AG25: Audit log requerido si se deriva, corrige, bloquea o modifica ruta crítica. | AH25: PM | AI25: PF; MoC | AJ25: Condicional | AK25: business_process_candidate | AL25: Representa ubicación sistémica de la actividad, no receptor inmediato solamente. | AM25: PM↔PF; PM↔MoC | AN25: Sí | AO25: S1; S2; S3; S4; S5 | AP25: S1 | S2 | S3 | S4 | S5 | AQ25: No directo | AR25: preparación; no diagnóstico | AS25: alta | AT25: SCR; EvidenceBundle; MDSB; Inventory PM candidates | AU25: GapObject / EvidenceInsufficiency | AV25: explicitly_carried_forward if unresolved | AW25: La escena queda sin proceso contenedor y se dificulta toda lectura de cadena de valor o relación con unidades operativas. | AX25: 6af28ed6cca9a5b5bc6df702172be54456e2ea27293ae8118cbb4512fc6291b3
A26: 0.1.0 | B26: 1.0 | C26: B0_5_0_5_3 | D26: C1B0_5-008 | E26: 0.5 | F26: 8 | G26: 0.5.3 | H26: Bloque_0_5_Documento_Madre_Capa1_v2_1_EVE.docx | I26: Versión del documento: 0.1 de trabajo | Base estructural: Diseno_Formal_Capa1_v2_1_Unificado | Base de redacción operativa: Marco de Trabajo y Catálogo de Preguntas v2.1 - Bloque 0.5 (Encuadre) | J26: Fuente canónica de nodos | K26: Fuente final aprobada | L26: 10 | M26: active | N26: base_question | O26: base | P26: encuadre_sistemico | Q26: Cuando terminas esta actividad con éxito, ¿qué hito importante se desbloquea en la empresa para que otros puedan avanzar? | R26: Siempre | S26: Cuando terminas esta actividad con éxito, ¿qué hito importante se desbloquea en la empresa para que otros puedan avanzar? | T26: Siempre | U26: Obligatoria | V26: scene_enabled_milestone | X26: normal | Y26: FALSE | AA26: capturado (captured_user_evidence) | AB26: captured_user_evidence | AC26: capturado (captured_user_evidence) | AD26: captured_user_evidence | AE26: No aplica / captura directa | AF26: No inferir como captured_user_evidence; exigir confirmación si afecta ruta canónica. | AG26: Audit log requerido si se deriva, corrige, bloquea o modifica ruta crítica. | AH26: PM | AI26: PF; MoC | AJ26: Condicional | AK26: target_state_candidate | AL26: Representa ubicación sistémica de la actividad, no receptor inmediato solamente. | AM26: PM↔PF; PM↔MoC | AN26: Sí | AO26: S1; S2; S3; S4; S5 | AP26: S1 | S2 | S3 | S4 | S5 | AQ26: No directo | AR26: preparación; no diagnóstico | AS26: alta | AT26: SCR; EvidenceBundle; MDSB; Inventory PM candidates | AU26: GapObject / EvidenceInsufficiency | AV26: explicitly_carried_forward if unresolved | AW26: La escena queda sin relación explícita con el avance que habilita y se vuelve difícil mapear su lugar en la secuencia de hitos. | AX26: 6298bd957d6aa9fdc8347a9a07b0dd1d956d90ae06c9d8c23237b45d6f86ea54
